# `try...catch`와 에러 핸들링

🔎  `try…catch` 를 사용했을 때 어떤 점이 좋을까요? 

🔎
```javascript
try {
  setTimeout(function() {
    noSuchVariable; // 스크립트는 여기서 죽습니다.
  }, 1000);
} catch (e) {
  alert( "작동 멈춤" );
}

```
위 코드에서 발생한 예외는 `try..catch` 잡히지 않습니다. 
`setTimeout`처럼 ‘스케줄 된(scheduled)’ 코드에서 발생한 예외는 `try..catch`에서 잡아낼 수 없습니다. 왜 그럴까요? 

🔎
```javascript
function func() {

  try {
    return 1;

  } catch (e) {
    /* ... */
  } finally {
    alert( 'finally' );
  }
}

alert( func() ); 
```
위 코드는 어떤 순서대로 실행될까요?
